Workbook

Sheet 报水情科
A3: 安 康 水 文 局 土 壤 墒 情 监 测 数 据 表
A4: 填表日期： 2026年5月11日 8时30分 采 样 天 气：晴天
A7: 站名编码 | B7: 站 名 | C7: 土壤垂线重量含水率（%） | F7: 垂线平均重量含水率（%） | G7: 田间持水量（%） | H7: 土壤湿度（%） | I7: 作物种 类 | J7: 作物生 长期
C8: 10cm(%) | D8: 20cm (%) | E8: 40cm(%)
A9: 618A0900 | B9: 石 泉 | C9: =报勘测处!J5 -> 24.2 | D9: =报勘测处!K5 -> 26.2 | E9: =报勘测处!L5 -> 21.6 | F9: =报勘测处!M5 -> 24.3 | G9: =报勘测处!N5 -> 30.7 | H9: =报勘测处!O5 -> 79.153094 | I9: 蔬菜 | J9: =报勘测处!W5 -> 成长期
A10: 618A9800 | B10: 马 池 | C10: =报勘测处!J6 -> 20.2 | D10: =报勘测处!K6 -> 22.9 | E10: =报勘测处!L6 -> 24.5 | F10: =报勘测处!M6 -> 22.2875 | G10: =报勘测处!N6 -> 28.08 | H10: =报勘测处!O6 -> 79.371439 | I10: =报勘测处!V6 -> 白地 | J10: =报勘测处!W6 -> 无
A11: 618A1000 | B11: 长枪铺 | C11: =报勘测处!J7 -> 26.8 | D11: =报勘测处!K7 -> 22.6 | E11: =报勘测处!L7 -> 21.3 | F11: =报勘测处!M7 -> 23.85 | G11: =报勘测处!N7 -> 27 | H11: =报勘测处!O7 -> 88.333333 | I11: =报勘测处!V7 -> 蔬菜 | J11: =报勘测处!W7 -> 生长期
A12: 618A1200 | B12: 恒 口 | C12: =报勘测处!J8 -> 20.3 | D12: =报勘测处!K8 -> 22.3 | E12: =报勘测处!L8 -> 21.2 | F12: =报勘测处!M8 -> 21.275 | G12: =报勘测处!N8 -> 25.45 | H12: =报勘测处!O8 -> 83.595285 | I12: 蔬菜 | J12: =报勘测处!W8 -> 成长期
A13: 备 注
A14: =报勘测处!A10 -> 一校：张岚 2026年5月11日 二校： 吴丹 2026年5月11日 审查：白龙军 2026年5月11日

Sheet 报勘测处
A1: 附表4 2025年安康水文局土壤墒情监测报表
A2: 站 名 | B2: 测 次 | C2: 监测时间 | F2: 监测方法及监测深度土壤含水量 | N2: 田 间 持 水 量 （%） | O2: 相 对 湿 度 (%) | P2: 连 续 无 雨 日 (d) | Q2: 时段降水量（mm) | R2: 平均 流 量(108m3) | S2: 时 段 蒸 发 量（mm) | T2: 灌溉 时间 | V2: 作物生长情况 | Y2: 备 注
C3: 月 | D3: 日 | E3: 时 | F3: 仪器法 （体积 %） | J3: 烘干法（重量 %） | T3: 月 | U3: 日 | V3: 种类 | W3: 生长 阶段 | X3: 水分状态
F4: 10cm | G4: 20cm | H4: 40cm | I4: 垂线 平均 | J4: 10cm | K4: 20cm | L4: 40cm | M4: 垂线 平均
A5: 石 泉 | B5: 13 | C5: 5 | D5: 10 | E5: 0.33333333 | F5: 仪器故障，无仪器观测值 | J5: =站上报送原始1!R9 -> 24.2 | K5: =站上报送原始1!S9 -> 26.2 | L5: =站上报送原始1!T9 -> 21.6 | M5: =站上报送原始1!U9 -> 24.3 | N5: =站上报送原始1!V9 -> 30.7 | O5: =站上报送原始1!W9 -> 79.153094 | P5: =站上报送原始1!I16 -> 3 | Q5: =站上报送原始1!I14 -> 7.3 | R5: =旬总流量计算!C3 -> 1.08864 | V5: =站上报送原始1!B13 -> 蔬菜 | W5: =站上报送原始1!B14 -> 成长期 | X5: =站上报送原始1!B15 -> 正常 | Y5: 采样天气:晴天
A6: 马 池 | B6: 13 | C6: 5 | D6: 10 | E6: 0.33680556 | J6: =站上报送原始1!R28 -> 20.2 | K6: =站上报送原始1!S28 -> 22.9 | L6: =站上报送原始1!T28 -> 24.5 | M6: =站上报送原始1!U28 -> 22.2875 | N6: =站上报送原始1!V28 -> 28.08 | O6: =站上报送原始1!W28 -> 79.371439 | P6: =站上报送原始1!I35 -> 3 | Q6: =站上报送原始1!I33 -> 10.9 | R6: =旬总流量计算!C4 -> 0.0546912 | S6: =站上报送原始1!I34 -> 28.7 | V6: =站上报送原始1!B32 -> 白地 | W6: =站上报送原始1!B33 -> 无 | X6: =站上报送原始1!B34 -> 正常
A7: 长枪铺 | B7: 13 | C7: 5 | D7: 10 | E7: 0.33333333 | J7: =站上报送原始1!R47 -> 26.8 | K7: =站上报送原始1!S47 -> 22.6 | L7: =站上报送原始1!T47 -> 21.3 | M7: =站上报送原始1!U47 -> 23.85 | N7: =站上报送原始1!P44 -> 27 | O7: =站上报送原始1!W47 -> 88.333333 | P7: =站上报送原始1!I54 -> 3 | Q7: =站上报送原始1!I52 -> 17.1 | R7: =旬总流量计算!C5 -> 0.121824 | V7: =站上报送原始1!B51 -> 蔬菜 | W7: =站上报送原始1!B52 -> 生长期 | X7: =站上报送原始1!B53 -> 正常
A8: 恒 口 | B8: 13 | C8: 5 | D8: 10 | E8: 0.33333333 | J8: =站上报送原始1!R66 -> 20.3 | K8: =站上报送原始1!S66 -> 22.3 | L8: =站上报送原始1!T66 -> 21.2 | M8: =站上报送原始1!U66 -> 21.275 | N8: =站上报送原始1!V66 -> 25.45 | O8: =站上报送原始1!W66 -> 83.595285 | P8: =站上报送原始1!I73 -> 3 | Q8: =站上报送原始1!I71 -> 12.8 | R8: =旬总流量计算!C6 -> 0.0157248 | S8: =站上报送原始1!I72 -> 29.2 | V8: =站上报送原始1!B70 -> 蔬菜 | W8: =站上报送原始1!B71 -> 成长期 | X8: =站上报送原始1!B72 -> 正常
A9: 说 明
A10: 一校：张岚 2026年5月11日 二校： 吴丹 2026年5月11日 审查：白龙军 2026年5月11日

Sheet 站上报送原始1
A1: 附件2 石 泉 站 土 壤 墒 情 监 测 烘 干 法 计 算 表
A2: 测次：13 采样时间: 2026 年 5 月 10 日 8 时 00分 烘干温度：105℃ 烘干时间： 10 日 8 时 25 分 ～ 10 日 16 时 25 分
C3: 取样深度（cm） | L3: 垂线平均土壤含水量（%） | O3: 加权垂线平均 | P3: 田间 持水量（%） | Q3: 土壤相 对湿度（%）
C4: 10 | F4: 20 | I4: 40
A5: 称样容器编号 | C5: 31 | D5: 32 | E5: 33 | F5: 34 | G5: 35 | H5: 36 | I5: 37 | J5: 38 | K5: 39 | L5: 1 | M5: 2 | N5: 3
A6: 称样容器+湿土质量（g） | B6: 1 | C6: 78.4 | D6: 79.9 | E6: 80.7 | F6: 79.3 | G6: 80.9 | H6: 81.8 | I6: 74.7 | J6: 75.4 | K6: 76.5 | L6: =C12 -> 24.234541 | M6: =F12 -> 26.172545 | N6: =I12 -> 21.579431 | O6: =(3*L6+3*M6+2*N6)/8 -> 24.297515 | P6: 30.7 | Q6: =O6/P6*100 -> 79.145
A7: 称样容器+干土质量（g） | B7: 2 | C7: 66.3 | D7: 67.5 | E7: 67.8 | F7: 66.5 | G7: 67.4 | H7: 68.1 | I7: 64.6 | J7: 64.8 | K7: 65.6
A8: 称样容器质量（g） | B8: 3 | C8: 15.6 | D8: 16 | E8: 15.7 | F8: 16.7 | G8: 16.1 | H8: 16.4 | I8: 16.7 | J8: 15.9 | K8: 16 | R8: 手动输入 | U8: 自动计算检查0为“通过”
A9: 干土质量（g） | B9: 4=2-3 | C9: =C7-C8 -> 50.7 | D9: =D7-D8 -> 51.5 | E9: =E7-E8 -> 52.1 | F9: =F7-F8 -> 49.8 | G9: =G7-G8 -> 51.3 | H9: =H7-H8 -> 51.7 | I9: =I7-I8 -> 47.9 | J9: =J7-J8 -> 48.9 | K9: =K7-K8 -> 49.6 | R9: 24.2 | S9: 26.2 | T9: 21.6 | U9: =(3*R9+3*S9+2*T9)/8 -> 24.3 | V9: 30.7 | W9: =U9/V9*100 -> 79.153094
A10: 土壤水质量（g） | B10: 5=1-2 | C10: =C6-C7 -> 12.1 | D10: =D6-D7 -> 12.4 | E10: =E6-E7 -> 12.9 | F10: =F6-F7 -> 12.8 | G10: =G6-G7 -> 13.5 | H10: =H6-H7 -> 13.7 | I10: =I6-I7 -> 10.1 | J10: =J6-J7 -> 10.6 | K10: =K6-K7 -> 10.9
A11: 土壤含水量（%） | B11: 5/4*100 | C11: =C10/C9*100 -> 23.865878 | D11: =D10/D9*100 -> 24.07767 | E11: =E10/E9*100 -> 24.760077 | F11: =F10/F9*100 -> 25.702811 | G11: =G10/G9*100 -> 26.315789 | H11: =H10/H9*100 -> 26.499033 | I11: =I10/I9*100 -> 21.085595 | J11: =J10/J9*100 -> 21.676892 | K11: =K10/K9*100 -> 21.975806
A12: 测点平均土壤含水量（%） | C12: =(C11+D11+E11)/3 -> 24.234541 | F12: =(F11+G11+H11)/3 -> 26.172545 | I12: =(I11+J11+K11)/3 -> 21.579431
A13: 主 要 作 物 | B13: 蔬菜 | G13: 地下水埋深 （m） | I13: 无 | J13: 表土情况 | L13: 采样天气状况 | N13: 主要作物生长描述
A14: 主要作物生长阶段 | B14: 成长期 | G14: 旬降水量（mm） | I14: 7.3 | J14: 无干土 | L14: 晴天 | N14: 正常
A15: 主要作物水分状况 | B15: 正常 | G15: 旬流量（㎥/s） | I15: 126
A16: 土壤类型 | B16: 褐土 | G16: 连续无雨日 | I16: 3 | U16: =U9-O6 -> 0.0024849964 | V16: =V9-P6 -> 0 | W16: =W9-Q6 -> 0.0080944508
A17: 土壤质地 | B17: 黏土 | G17: 灌溉时间 | I17: 无
A18: 取样: 喻 林 测定： 喻 林 一校：沈杭 二校：金 露 审核：
A20: 马 池 站 土 壤 墒 情 监 测 烘 干 法 计 算 表
A21: 测次：13 采样时间：2026年05月10日08时05分 烘干温度 105℃ 烘干时间 10日08时40分-10日18时20分
A22: 项目 | C22: 取样深度（cm） | L22: 垂线平均土壤含水量（%） | O22: 加权垂线平均 | P22: 田间 持水量（%） | Q22: 土壤相 对湿度（%）
C23: 10 | F23: 20 | I23: 40
A24: 称样容器编号 | C24: 22 | D24: 23 | E24: 24 | F24: 25 | G24: 26 | H24: 27 | I24: 28 | J24: 29 | K24: 30 | L24: 1 | M24: 2 | N24: 3
A25: 称样容器+湿土质量（g） | B25: 1 | C25: 68.6 | D25: 76.1 | E25: 74.1 | F25: 71.8 | G25: 67 | H25: 64.5 | I25: 72.9 | J25: 77.7 | K25: 78.7 | L25: =C31 -> 20.177967 | M25: =F31 -> 22.866305 | N25: =I31 -> 24.477289 | O25: =(C31*3+F31*3+I31*2)/8 -> 22.260924 | P25: 28.08 | Q25: =O25/P25*100 -> 79.276797
A26: 称样容器+干土质量（g） | B26: 2 | C26: 59.8 | D26: 66 | E26: 64.3 | F26: 61.4 | G26: 57.4 | H26: 55.4 | I26: 61.8 | J26: 65.5 | K26: 66.3
A27: 称样容器质量（g） | B27: 3 | C27: 15.8 | D27: 15.9 | E27: 16.2 | F27: 15.6 | G27: 15.5 | H27: 15.8 | I27: 15.9 | J27: 15.9 | K27: 16 | U27: 自动计算检查0为“通过”
A28: 干土质量（g） | B28: 4=2-3 | C28: =C26-C27 -> 44 | D28: =D26-D27 -> 50.1 | E28: =E26-E27 -> 48.1 | F28: =F26-F27 -> 45.8 | G28: =G26-G27 -> 41.9 | H28: =H26-H27 -> 39.6 | I28: =I26-I27 -> 45.9 | J28: =J26-J27 -> 49.6 | K28: =K26-K27 -> 50.3 | R28: 20.2 | S28: 22.9 | T28: 24.5 | U28: =(R28*3+S28*3+T28*2)/8 -> 22.2875 | V28: =P25 -> 28.08 | W28: =U28/V28*100 -> 79.371439
A29: 土壤水质量（g） | B29: 5=1-2 | C29: =C25-C26 -> 8.8 | D29: =D25-D26 -> 10.1 | E29: =E25-E26 -> 9.8 | F29: =F25-F26 -> 10.4 | G29: =G25-G26 -> 9.6 | H29: =H25-H26 -> 9.1 | I29: =I25-I26 -> 11.1 | J29: =J25-J26 -> 12.2 | K29: =K25-K26 -> 12.4
A30: 土壤含水量（%） | B30: 5/4*100 | C30: =C29/C28*100 -> 20 | D30: =D29/D28*100 -> 20.159681 | E30: =E29/E28*100 -> 20.37422 | F30: =F29/F28*100 -> 22.707424 | G30: =G29/G28*100 -> 22.911695 | H30: =H29/H28*100 -> 22.979798 | I30: =I29/I28*100 -> 24.183007 | J30: =J29/J28*100 -> 24.596774 | K30: =K29/K28*100 -> 24.652087
A31: 测点平均土壤含水量（%） | C31: =(C30+D30+E30)/3 -> 20.177967 | F31: =(F30+G30+H30)/3 -> 22.866305 | I31: =(I30+J30+K30)/3 -> 24.477289
A32: 主 要 作 物 | B32: 白地 | G32: 地下水埋深 （m） | J32: 表土情况 | L32: 采样天气状况 | N32: 主要作物生长描述
A33: 主要作物生长阶段 | B33: 无 | G33: 时段降水量（mm） | I33: 10.9 | J33: 正常 | L33: 晴 | N33: 正常
A34: 主要作物水分状况 | B34: 正常 | G34: 时段蒸发量 （mm） | I34: 28.7
A35: 土壤类型 | B35: 褐土 | G35: 连续无雨日 | I35: 3 | U35: =U28-O25 -> 0.026575514 | V35: =V28-P25 -> 0 | W35: =W28-Q25 -> 0.094642144
A36: 土壤质地 | B36: 黏土 | G36: 时段平均流量 | I36: 6.33
A37: 取样:尹顺 测定：尹顺 一校： 二校： 审核：
A39: 附件2 长枪铺 站 土 壤 墒 情 监 测 烘 干 法 计 算 表
A40: 测次：13 采样时间: 2026年5月10日 8 时 烘干温度：105℃ 烘干时间：2026年5月10日8时30分～2026年5月10日16时30分
A41: 项目 | C41: 取样深度（cm） | L41: 垂线平均土壤含水量（%） | O41: 加权垂线平均 | P41: 田间 持水量（%） | Q41: 土壤相 对湿度（%）
C42: 10 | F42: 20 | I42: 40
...

Sheet 恒口原始2
A1: 附表4 2025年安康水文局土壤墒情监测报表
A2: 站 名 | B2: 测 次 | C2: 监测时间 | F2: 监测方法及监测深度土壤含水量 | N2: 田 间 持 水 量 （%） | O2: 相 对 湿 度 (%) | P2: 连 续 无 雨 日 (d) | Q2: 时段降水量（mm) | R2: 旬 径 流 量(108m3) | S2: 时 段 蒸 发 量（mm) | T2: 灌溉 时间 | V2: 作物生长情况 | Y2: 备 注
C3: 月 | D3: 日 | E3: 时 | F3: 仪器法 （体积 %） | J3: 烘干法（重量 %） | T3: 月 | U3: 日 | V3: 种类 | W3: 生长 阶段 | X3: 水分状态
F4: 10cm | G4: 20cm | H4: 40cm | I4: 垂线 平均 | J4: 10cm | K4: 20cm | L4: 40cm | M4: 垂线 平均
A5: 恒 口 | B5: 13 | C5: 5 | D5: 10 | E5: 0.33333333 | J5: =[1]恒口!L6 -> 20.268077 | K5: =[1]恒口!M6 -> 22.303308 | L5: =[1]恒口!N6 -> 21.175819 | M5: =[1]恒口!O6 -> 21.258224 | N5: =[1]恒口!P6 -> 25.45 | O5: =[1]恒口!Q6 -> 83.529367 | P5: =[1]恒口!I16 -> 3 | Q5: =[1]恒口!I14 -> 12.8 | R5: 1.82 | S5: 29.2 | V5: =[1]恒口!B13 -> 蔬菜 | W5: =[1]恒口!B14 -> 成长期 | X5: 正常
A6: 说 明
A7: 制表：马德志 一校 ： 马 德志

Sheet 旬总流量计算
B1: 站上旬日均流量 | C1: 报送旬总流量
B2: 立方米每秒 | C2: 亿立方米每秒
A3: 石泉 | B3: =站上报送原始1!I15 -> 126 | C3: =86400*10*B3*0.00000001 -> 1.08864
A4: 马池 | B4: =站上报送原始1!I36 -> 6.33 | C4: =86400*10*B4*0.00000001 -> 0.0546912
A5: 长枪铺 | B5: =站上报送原始1!I53 -> 14.1 | C5: =86400*10*B5*0.00000001 -> 0.121824
A6: 恒口 | B6: =恒口原始2!R5 -> 1.82 | C6: =86400*10*B6*0.00000001 -> 0.0157248

Sheet 对比检查
A1: 垂线平均重量含水率（%） | B1: 田间持水量（%） | C1: 土壤 湿度（%）
A3: =报水情科!F9-报勘测处!M5 -> 0 | B3: =报水情科!G9-报勘测处!N5 -> 0 | C3: =报水情科!H9-报勘测处!O5 -> 0
A4: =报水情科!F10-报勘测处!M6 -> 0 | B4: =报水情科!G10-报勘测处!N6 -> 0 | C4: =报水情科!H10-报勘测处!O6 -> 0
A5: =报水情科!F11-报勘测处!M7 -> 0 | B5: =报水情科!G11-报勘测处!N7 -> 0 | C5: =报水情科!H11-报勘测处!O7 -> 0
A6: =报水情科!F12-报勘测处!M8 -> 0 | B6: =报水情科!G12-报勘测处!N8 -> 0 | C6: =报水情科!H12-报勘测处!O8 -> 0
A7: 全部为0通过
